<?xml version="1.0" encoding="utf-8"?>
<!-- This URDF was automatically created by SolidWorks to URDF Exporter! Originally created by Stephen Brawner (brawner@gmail.com) 
     Commit Version: 1.5.1-0-g916b5db  Build Version: 1.5.7152.31018
     For more information, please see http://wiki.ros.org/sw_urdf_exporter -->
<robot
  name="4wheel_castle2">
  <link
    name="base">
    <inertial>
      <origin
        xyz="-0.101222450007234 0.0611878805385779 0.134712291964518"
        rpy="0 0 0" />
      <mass
        value="5.04599768700975" />
      <inertia
        ixx="0.0199585188421209"
        ixy="3.5792448395538E-07"
        ixz="-8.4963369555268E-07"
        iyy="0.0204011323429147"
        iyz="8.69413175240226E-06"
        izz="0.0133780567917248" />
    </inertial>
    <visual>
      <origin
        xyz="0 0 0"
        rpy="0 0 0" />
      <geometry>
        <mesh
          filename="package://4wheel_castle2/meshes/base.STL" />
      </geometry>
      <material
        name="">
        <color
          rgba="0.752941176470588 0.752941176470588 0.752941176470588 1" />
      </material>
    </visual>
    <collision>
      <origin
        xyz="0 0 0"
        rpy="0 0 0" />
      <geometry>
        <mesh
          filename="package://4wheel_castle2/meshes/base.STL" />
      </geometry>
    </collision>
  </link>
  <link
    name="LFS">
    <inertial>
      <origin
        xyz="0.066688 -0.025617 0.027258"
        rpy="0 0 0" />
      <mass
        value="0.26437" />
      <inertia
        ixx="3.2075E-05"
        ixy="-1.4412E-07"
        ixz="-6.3085E-08"
        iyy="6.227E-05"
        iyz="-2.0189E-07"
        izz="6.2852E-05" />
    </inertial>
    <visual>
      <origin
        xyz="0 0 0"
        rpy="0 0 0" />
      <geometry>
        <mesh
          filename="package://4wheel_castle2/meshes/LFS.STL" />
      </geometry>
      <material
        name="">
        <color
          rgba="0.75294 0.75294 0.75294 1" />
      </material>
    </visual>
    <collision>
      <origin
        xyz="0 0 0"
        rpy="0 0 0" />
      <geometry>
        <mesh
          filename="package://4wheel_castle2/meshes/LFS.STL" />
      </geometry>
    </collision>
  </link>
  <joint
    name="LFS"
    type="prismatic">
    <origin
      xyz="-0.30216 -0.05081 0.029427"
      rpy="2.834 0 0" />
    <parent
      link="base" />
    <child
      link="LFS" />
    <axis
      xyz="0 0.3028 -0.95305" />
    <limit
      lower="0"
      upper="0"
      effort="0"
      velocity="0" />
  </joint>
  <link
    name="LFW">
    <inertial>
      <origin
        xyz="-0.012316 -2.7756E-17 5.8981E-17"
        rpy="0 0 0" />
      <mass
        value="0.19359" />
      <inertia
        ixx="0.00025308"
        ixy="2.0397E-19"
        ixz="-4.8808E-19"
        iyy="0.00013682"
        iyz="1.6941E-21"
        izz="0.00013682" />
    </inertial>
    <visual>
      <origin
        xyz="0 0 0"
        rpy="0 0 0" />
      <geometry>
        <mesh
          filename="package://4wheel_castle2/meshes/LFW.STL" />
      </geometry>
      <material
        name="">
        <color
          rgba="1 1 1 1" />
      </material>
    </visual>
    <collision>
      <origin
        xyz="0 0 0"
        rpy="0 0 0" />
      <geometry>
        <mesh
          filename="package://4wheel_castle2/meshes/LFW.STL" />
      </geometry>
    </collision>
  </link>
  <joint
    name="LFW"
    type="continuous">
    <origin
      xyz="0.00041099 -0.047479 0.052309"
      rpy="1.2177 0 -3.1416" />
    <parent
      link="LFS" />
    <child
      link="LFW" />
    <axis
      xyz="1 0 0" />
    <limit
      effort="3.1"
      velocity="7" />
  </joint>
  <link
    name="RFS">
    <inertial>
      <origin
        xyz="0.072447 -0.031683 0.02534"
        rpy="0 0 0" />
      <mass
        value="0.26437" />
      <inertia
        ixx="3.2075E-05"
        ixy="1.4412E-07"
        ixz="6.3085E-08"
        iyy="6.227E-05"
        iyz="-2.0189E-07"
        izz="6.2852E-05" />
    </inertial>
    <visual>
      <origin
        xyz="0 0 0"
        rpy="0 0 0" />
      <geometry>
        <mesh
          filename="package://4wheel_castle2/meshes/RFS.STL" />
      </geometry>
      <material
        name="">
        <color
          rgba="0.75294 0.75294 0.75294 1" />
      </material>
    </visual>
    <collision>
      <origin
        xyz="0 0 0"
        rpy="0 0 0" />
      <geometry>
        <mesh
          filename="package://4wheel_castle2/meshes/RFS.STL" />
      </geometry>
    </collision>
  </link>
  <joint
    name="RFS"
    type="prismatic">
    <origin
      xyz="0.10792 -0.012126 0.029427"
      rpy="2.834 0 -3.1416" />
    <parent
      link="base" />
    <child
      link="RFS" />
    <axis
      xyz="0 0.3028 -0.95305" />
    <limit
      lower="0"
      upper="0"
      effort="0"
      velocity="0" />
  </joint>
  <link
    name="RFW">
    <inertial>
      <origin
        xyz="-0.012316 -4.4409E-16 2.7756E-16"
        rpy="0 0 0" />
      <mass
        value="0.19359" />
      <inertia
        ixx="0.00025308"
        ixy="9.8823E-24"
        ixz="5.1839E-21"
        iyy="0.00013682"
        iyz="4.2352E-22"
        izz="0.00013682" />
    </inertial>
    <visual>
      <origin
        xyz="0 0 0"
        rpy="0 0 0" />
      <geometry>
        <mesh
          filename="package://4wheel_castle2/meshes/RFW.STL" />
      </geometry>
      <material
        name="">
        <color
          rgba="1 1 1 1" />
      </material>
    </visual>
    <collision>
      <origin
        xyz="0 0 0"
        rpy="0 0 0" />
      <geometry>
        <mesh
          filename="package://4wheel_castle2/meshes/RFW.STL" />
      </geometry>
    </collision>
  </link>
  <joint
    name="RFW"
    type="continuous">
    <origin
      xyz="0.0061708 -0.028286 0.058405"
      rpy="-1.8458 0 -3.1416" />
    <parent
      link="RFS" />
    <child
      link="RFW" />
    <axis
      xyz="1 0 0" />
    <limit
      effort="3.1"
      velocity="7" />
  </joint>
  <link
    name="LBS">
    <inertial>
      <origin
        xyz="0.075402 -0.020601 0.012626"
        rpy="0 0 0" />
      <mass
        value="0.19701" />
      <inertia
        ixx="1.688E-05"
        ixy="2.0771E-19"
        ixz="-1.6354E-19"
        iyy="5.0218E-05"
        iyz="1.0509E-06"
        izz="4.7245E-05" />
    </inertial>
    <visual>
      <origin
        xyz="0 0 0"
        rpy="0 0 0" />
      <geometry>
        <mesh
          filename="package://4wheel_castle2/meshes/LBS.STL" />
      </geometry>
      <material
        name="">
        <color
          rgba="0.75294 0.75294 0.75294 1" />
      </material>
    </visual>
    <collision>
      <origin
        xyz="0 0 0"
        rpy="0 0 0" />
      <geometry>
        <mesh
          filename="package://4wheel_castle2/meshes/LBS.STL" />
      </geometry>
    </collision>
  </link>
  <joint
    name="LBS"
    type="prismatic">
    <origin
      xyz="-0.30216 -0.18919 -0.015774"
      rpy="-0.30763 0 0" />
    <parent
      link="base" />
    <child
      link="LBS" />
    <axis
      xyz="0 0.3028 -0.95305" />
    <limit
      lower="0"
      upper="0"
      effort="0"
      velocity="0" />
  </joint>
  <link
    name="LBC">
    <inertial>
      <origin
        xyz="0.00221267724899019 -8.10587101562968E-05 2.77555756156289E-17"
        rpy="0 0 0" />
      <mass
        value="0.0324803918529465" />
      <inertia
        ixx="8.86383358400043E-06"
        ixy="1.20679092415291E-06"
        ixz="-2.43521972335611E-21"
        iyy="2.82924094574379E-06"
        iyz="5.82756204115591E-21"
        izz="1.07052324634925E-05" />
    </inertial>
    <visual>
      <origin
        xyz="0 0 0"
        rpy="0 0 0" />
      <geometry>
        <mesh
          filename="package://4wheel_castle2/meshes/LBC.STL" />
      </geometry>
      <material
        name="">
        <color
          rgba="0.898039215686275 0.917647058823529 0.929411764705882 1" />
      </material>
    </visual>
    <collision>
      <origin
        xyz="0 0 0"
        rpy="0 0 0" />
      <geometry>
        <mesh
          filename="package://4wheel_castle2/meshes/LBC.STL" />
      </geometry>
    </collision>
  </link>
  <joint
    name="LBC"
    type="continuous">
    <origin
      xyz="0.041161 -0.015068 -0.0047875"
      rpy="1.2653 -0.036921 3.0251" />
    <parent
      link="LBS" />
    <child
      link="LBC" />
    <axis
      xyz="0 1 0" />
  </joint>
  <link
    name="LBW">
    <inertial>
      <origin
        xyz="-0.0155089419428623 -0.0184390197293757 -0.0160336018603206"
        rpy="0 0 0" />
      <mass
        value="0.193585420779862" />
      <inertia
        ixx="0.000253081141332253"
        ixy="9.06325253562101E-20"
        ixz="1.03338019565025E-19"
        iyy="0.000136818598566516"
        iyz="-3.3881317890172E-21"
        izz="0.000136818598566516" />
    </inertial>
    <visual>
      <origin
        xyz="0 0 0"
        rpy="0 0 0" />
      <geometry>
        <mesh
          filename="package://4wheel_castle2/meshes/LBW.STL" />
      </geometry>
      <material
        name="">
        <color
          rgba="1 1 1 1" />
      </material>
    </visual>
    <collision>
      <origin
        xyz="0 0 0"
        rpy="0 0 0" />
      <geometry>
        <mesh
          filename="package://4wheel_castle2/meshes/LBW.STL" />
      </geometry>
    </collision>
  </link>
  <joint
    name="LBW"
    type="continuous">
    <origin
      xyz="0.043943 -0.003028 0.020135"
      rpy="0.2527 0 0" />
    <parent
      link="LBC" />
    <child
      link="LBW" />
    <axis
      xyz="1 0 0" />
    <limit
      effort="3.1"
      velocity="7" />
  </joint>
  <link
    name="RBS">
    <inertial>
      <origin
        xyz="0.075402 -0.0095357 -0.022201"
        rpy="0 0 0" />
      <mass
        value="0.19701" />
      <inertia
        ixx="1.688E-05"
        ixy="-8.6209E-20"
        ixz="-8.6491E-21"
        iyy="5.0218E-05"
        iyz="1.0509E-06"
        izz="4.7245E-05" />
    </inertial>
    <visual>
      <origin
        xyz="0 0 0"
        rpy="0 0 0" />
      <geometry>
        <mesh
          filename="package://4wheel_castle2/meshes/RBS.STL" />
      </geometry>
      <material
        name="">
        <color
          rgba="0.75294 0.75294 0.75294 1" />
      </material>
    </visual>
    <collision>
      <origin
        xyz="0 0 0"
        rpy="0 0 0" />
      <geometry>
        <mesh
          filename="package://4wheel_castle2/meshes/RBS.STL" />
      </geometry>
    </collision>
  </link>
  <joint
    name="RBS"
    type="prismatic">
    <origin
      xyz="0.10216 -0.18919 -0.015774"
      rpy="2.834 0 -3.1416" />
    <parent
      link="base" />
    <child
      link="RBS" />
    <axis
      xyz="0 0.3028 -0.95305" />
    <limit
      lower="0"
      upper="0"
      effort="0"
      velocity="0" />
  </joint>
  <link
    name="RBC">
    <inertial>
      <origin
        xyz="0.00221267724899018 -8.10587101562586E-05 -2.77555756156289E-17"
        rpy="0 0 0" />
      <mass
        value="0.0324803918529465" />
      <inertia
        ixx="8.86383358400041E-06"
        ixy="1.20679092415297E-06"
        ixz="-4.49986253228847E-22"
        iyy="2.82924094574381E-06"
        iyz="-1.42275065359121E-21"
        izz="1.07052324634925E-05" />
    </inertial>
    <visual>
      <origin
        xyz="0 0 0"
        rpy="0 0 0" />
      <geometry>
        <mesh
          filename="package://4wheel_castle2/meshes/RBC.STL" />
      </geometry>
      <material
        name="">
        <color
          rgba="0.898039215686275 0.917647058823529 0.929411764705882 1" />
      </material>
    </visual>
    <collision>
      <origin
        xyz="0 0 0"
        rpy="0 0 0" />
      <geometry>
        <mesh
          filename="package://4wheel_castle2/meshes/RBC.STL" />
      </geometry>
    </collision>
  </link>
  <joint
    name="RBC"
    type="continuous">
    <origin
      xyz="0.041161 -0.015068 -0.0047875"
      rpy="-1.8784 -0.003856 3.1295" />
    <parent
      link="RBS" />
    <child
      link="RBC" />
    <axis
      xyz="0 1 0" />
  </joint>
  <link
    name="RBW">
    <inertial>
      <origin
        xyz="0.0176794105128818 0 1.31838984174237E-16"
        rpy="0 0 0" />
      <mass
        value="0.193585420779862" />
      <inertia
        ixx="0.000253081141332254"
        ixy="9.89969757103464E-20"
        ixz="8.8196643888364E-19"
        iyy="0.000136818598566517"
        iyz="1.27054942088145E-21"
        izz="0.000136818598566517" />
    </inertial>
    <visual>
      <origin
        xyz="0 0 0"
        rpy="0 0 0" />
      <geometry>
        <mesh
          filename="package://4wheel_castle2/meshes/RBW.STL" />
      </geometry>
      <material
        name="">
        <color
          rgba="1 1 1 1" />
      </material>
    </visual>
    <collision>
      <origin
        xyz="0 0 0"
        rpy="0 0 0" />
      <geometry>
        <mesh
          filename="package://4wheel_castle2/meshes/RBW.STL" />
      </geometry>
    </collision>
  </link>
  <joint
    name="RBW"
    type="continuous">
    <origin
      xyz="0.010755 -0.016873 0"
      rpy="-1.5287 0 0" />
    <parent
      link="RBC" />
    <child
      link="RBW" />
    <axis
      xyz="1 0 0" />
    <limit
      effort="3.1"
      velocity="7" />
  </joint>
  <link
    name="Cam">
    <inertial>
      <origin
        xyz="-0.01933 0.10483 0.10576"
        rpy="0 0 0" />
      <mass
        value="0.084224" />
      <inertia
        ixx="2.9796E-05"
        ixy="-5.7052E-07"
        ixz="-4.8463E-07"
        iyy="1.3987E-05"
        iyz="1.6709E-08"
        izz="3.7024E-05" />
    </inertial>
    <visual>
      <origin
        xyz="0 0 0"
        rpy="0 0 0" />
      <geometry>
        <mesh
          filename="package://4wheel_castle2/meshes/Cam.STL" />
      </geometry>
      <material
        name="">
        <color
          rgba="0.75294 0.75294 0.75294 1" />
      </material>
    </visual>
    <collision>
      <origin
        xyz="0 0 0"
        rpy="0 0 0" />
      <geometry>
        <mesh
          filename="package://4wheel_castle2/meshes/Cam.STL" />
      </geometry>
    </collision>
  </link>
  <joint
    name="Cam"
    type="fixed">
    <origin
      xyz="0 0 0"
      rpy="0 0 1.5708" />
    <parent
      link="base" />
    <child
      link="Cam" />
    <axis
      xyz="0 0 0" />
  </joint>
  <link
    name="Lidar">
    <inertial>
      <origin
        xyz="0 0 0"
        rpy="0 0 0" />
      <mass
        value="0" />
      <inertia
        ixx="0"
        ixy="0"
        ixz="0"
        iyy="0"
        iyz="0"
        izz="0" />
    </inertial>
    <visual>
      <origin
        xyz="0 0 0"
        rpy="0 0 0" />
      <geometry>
        <mesh
          filename="package://4wheel_castle2/meshes/Lidar.STL" />
      </geometry>
      <material
        name="">
        <color
          rgba="1 1 1 1" />
      </material>
    </visual>
    <collision>
      <origin
        xyz="0 0 0"
        rpy="0 0 0" />
      <geometry>
        <mesh
          filename="package://4wheel_castle2/meshes/Lidar.STL" />
      </geometry>
    </collision>
  </link>
  <joint
    name="Lidar"
    type="fixed">
    <origin
      xyz="-0.23716 0.016589 -0.56869"
      rpy="1.5708 0 1.5973" />
    <parent
      link="base" />
    <child
      link="Lidar" />
    <axis
      xyz="0 0 0" />
  </joint>
</robot>